{"trial_id": "0000", "hyperparameters": {"space": [{"class_name": "Int", "config": {"name": "units", "default": null, "conditions": [], "min_value": 32, "max_value": 512, "step": 32, "sampling": "linear"}}, {"class_name": "Choice", "config": {"name": "learning_rate", "default": 0.1, "conditions": [], "values": [0.1, 0.01, 0.001, 0.0001], "ordered": true}}], "values": {"units": 384, "learning_rate": 0.01, "tuner/epochs": 2, "tuner/initial_epoch": 0, "tuner/bracket": 2, "tuner/round": 0}}, "metrics": {"metrics": {}}, "score": null, "best_step": 0, "status": "FAILED", "message": "Traceback (most recent call last):\n  File \"/Users/alessio/.pyenv/versions/3.10.6/envs/showupforhealth/lib/python3.10/site-packages/keras_tuner/engine/base_tuner.py\", line 270, in _try_run_and_update_trial\n    self._run_and_update_trial(trial, *fit_args, **fit_kwargs)\n  File \"/Users/alessio/.pyenv/versions/3.10.6/envs/showupforhealth/lib/python3.10/site-packages/keras_tuner/engine/base_tuner.py\", line 235, in _run_and_update_trial\n    results = self.run_trial(trial, *fit_args, **fit_kwargs)\n  File \"/Users/alessio/.pyenv/versions/3.10.6/envs/showupforhealth/lib/python3.10/site-packages/keras_tuner/tuners/hyperband.py\", line 425, in run_trial\n    return super().run_trial(trial, *fit_args, **fit_kwargs)\n  File \"/Users/alessio/.pyenv/versions/3.10.6/envs/showupforhealth/lib/python3.10/site-packages/keras_tuner/engine/tuner.py\", line 287, in run_trial\n    obj_value = self._build_and_fit_model(trial, *args, **copied_kwargs)\n  File \"/Users/alessio/.pyenv/versions/3.10.6/envs/showupforhealth/lib/python3.10/site-packages/keras_tuner/engine/tuner.py\", line 214, in _build_and_fit_model\n    results = self.hypermodel.fit(hp, model, *args, **kwargs)\n  File \"/Users/alessio/.pyenv/versions/3.10.6/envs/showupforhealth/lib/python3.10/site-packages/keras_tuner/engine/hypermodel.py\", line 144, in fit\n    return model.fit(*args, **kwargs)\n  File \"/Users/alessio/.pyenv/versions/3.10.6/envs/showupforhealth/lib/python3.10/site-packages/keras/utils/traceback_utils.py\", line 70, in error_handler\n    raise e.with_traceback(filtered_tb) from None\n  File \"/var/folders/k_/yz2p4wvx5y5gnrg1k1km4vl40000gn/T/__autograph_generated_file390hwib1.py\", line 15, in tf__train_function\n    retval_ = ag__.converted_call(ag__.ld(step_function), (ag__.ld(self), ag__.ld(iterator)), None, fscope)\nValueError: in user code:\n\n    File \"/Users/alessio/.pyenv/versions/3.10.6/envs/showupforhealth/lib/python3.10/site-packages/keras/engine/training.py\", line 1160, in train_function  *\n        return step_function(self, iterator)\n    File \"/Users/alessio/.pyenv/versions/3.10.6/envs/showupforhealth/lib/python3.10/site-packages/keras/engine/training.py\", line 1146, in step_function  **\n        outputs = model.distribute_strategy.run(run_step, args=(data,))\n    File \"/Users/alessio/.pyenv/versions/3.10.6/envs/showupforhealth/lib/python3.10/site-packages/keras/engine/training.py\", line 1135, in run_step  **\n        outputs = model.train_step(data)\n    File \"/Users/alessio/.pyenv/versions/3.10.6/envs/showupforhealth/lib/python3.10/site-packages/keras/engine/training.py\", line 998, in train_step\n        return self.compute_metrics(x, y, y_pred, sample_weight)\n    File \"/Users/alessio/.pyenv/versions/3.10.6/envs/showupforhealth/lib/python3.10/site-packages/keras/engine/training.py\", line 1092, in compute_metrics\n        self.compiled_metrics.update_state(y, y_pred, sample_weight)\n    File \"/Users/alessio/.pyenv/versions/3.10.6/envs/showupforhealth/lib/python3.10/site-packages/keras/engine/compile_utils.py\", line 605, in update_state\n        metric_obj.update_state(y_t, y_p, sample_weight=mask)\n    File \"/Users/alessio/.pyenv/versions/3.10.6/envs/showupforhealth/lib/python3.10/site-packages/keras/utils/metrics_utils.py\", line 77, in decorated\n        update_op = update_state_fn(*args, **kwargs)\n    File \"/Users/alessio/.pyenv/versions/3.10.6/envs/showupforhealth/lib/python3.10/site-packages/keras/metrics/base_metric.py\", line 143, in update_state_fn\n        return ag_update_state(*args, **kwargs)\n    File \"/Users/alessio/.pyenv/versions/3.10.6/envs/showupforhealth/lib/python3.10/site-packages/keras/metrics/metrics.py\", line 1052, in update_state  **\n        return metrics_utils.update_confusion_matrix_variables(\n    File \"/Users/alessio/.pyenv/versions/3.10.6/envs/showupforhealth/lib/python3.10/site-packages/keras/utils/metrics_utils.py\", line 674, in update_confusion_matrix_variables\n        y_pred.shape.assert_is_compatible_with(y_true.shape)\n\n    ValueError: Shapes (None, 384) and (None, 1) are incompatible\n\n"}